2023-08-27 19:26:22,764	Exception occurred:
<class 'RuntimeError'>: All connection attempts failed for host.docker.internal, use {phantom.connection_test: false} to disable it
  File "/usr/local/lib/python3.8/dist-packages/yandextank/core/tankworker.py", line 70, in run
    self.core.plugins_configure()

  File "/usr/local/lib/python3.8/dist-packages/yandextank/core/tankcore.py", line 262, in plugins_configure
    plugin.configure()

  File "/usr/local/lib/python3.8/dist-packages/yandextank/plugins/Phantom/plugin.py", line 67, in configure
    self.phantom_config = self.phantom.config_file

  File "/usr/local/lib/python3.8/dist-packages/yandextank/plugins/Phantom/plugin.py", line 76, in phantom
    self._phantom.read_config()

  File "/usr/local/lib/python3.8/dist-packages/yandextank/plugins/Phantom/utils.py", line 95, in read_config
    stream.read_config()

  File "/usr/local/lib/python3.8/dist-packages/yandextank/plugins/Phantom/utils.py", line 274, in read_config
    self.ipv6, self.resolved_ip, self.port, self.address = self.address_wizard.resolve(

  File "/usr/local/lib/python3.8/dist-packages/yandextank/common/util.py", line 587, in resolve
    raise RuntimeError(msg % address_str)

2023-08-27 19:30:12,985	Traceback (most recent call last):
  File "/usr/lib/python3/dist-packages/urllib3/contrib/pyopenssl.py", line 485, in wrap_socket
    cnx.do_handshake()
  File "/usr/local/lib/python3.8/dist-packages/OpenSSL/SSL.py", line 1907, in do_handshake
    self._raise_ssl_error(self._ssl, result)
  File "/usr/local/lib/python3.8/dist-packages/OpenSSL/SSL.py", line 1639, in _raise_ssl_error
    _raise_current_error()
  File "/usr/local/lib/python3.8/dist-packages/OpenSSL/_util.py", line 54, in exception_from_error_queue
    raise exception_type(errors)
OpenSSL.SSL.Error: [('SSL routines', '', 'unexpected eof while reading')]

During handling of the above exception, another exception occurred:

Traceback (most recent call last):
  File "/usr/lib/python3/dist-packages/urllib3/connectionpool.py", line 665, in urlopen
    httplib_response = self._make_request(
  File "/usr/lib/python3/dist-packages/urllib3/connectionpool.py", line 376, in _make_request
    self._validate_conn(conn)
  File "/usr/lib/python3/dist-packages/urllib3/connectionpool.py", line 996, in _validate_conn
    conn.connect()
  File "/usr/lib/python3/dist-packages/urllib3/connection.py", line 366, in connect
    self.sock = ssl_wrap_socket(
  File "/usr/lib/python3/dist-packages/urllib3/util/ssl_.py", line 370, in ssl_wrap_socket
    return context.wrap_socket(sock, server_hostname=server_hostname)
  File "/usr/lib/python3/dist-packages/urllib3/contrib/pyopenssl.py", line 491, in wrap_socket
    raise ssl.SSLError("bad handshake: %r" % e)
ssl.SSLError: ("bad handshake: Error([('SSL routines', '', 'unexpected eof while reading')])",)

During handling of the above exception, another exception occurred:

Traceback (most recent call last):
  File "/usr/lib/python3/dist-packages/requests/adapters.py", line 439, in send
    resp = conn.urlopen(
  File "/usr/lib/python3/dist-packages/urllib3/connectionpool.py", line 719, in urlopen
    retries = retries.increment(
  File "/usr/lib/python3/dist-packages/urllib3/util/retry.py", line 436, in increment
    raise MaxRetryError(_pool, url, error or ResponseError(cause))
urllib3.exceptions.MaxRetryError: HTTPSConnectionPool(host='overload.yandex.net', port=443): Max retries exceeded with url: /api/job/636995/configinitial.txt?api_token=f0abbbaf79844ac396743534e5fc5c73 (Caused by SSLError(SSLError("bad handshake: Error([('SSL routines', '', 'unexpected eof while reading')])")))

During handling of the above exception, another exception occurred:

Traceback (most recent call last):
  File "/usr/local/lib/python3.8/dist-packages/yandextank/plugins/DataUploader/client.py", line 215, in __make_api_request
    response = self.__send_single_request(request, next(ids), trace=trace)
  File "/usr/local/lib/python3.8/dist-packages/yandextank/plugins/DataUploader/client.py", line 153, in __send_single_request
    resp = self.session.send(p, timeout=self.connection_timeout)
  File "/usr/lib/python3/dist-packages/requests/sessions.py", line 646, in send
    r = adapter.send(request, **kwargs)
  File "/usr/lib/python3/dist-packages/requests/adapters.py", line 514, in send
    raise SSLError(e, request=request)
requests.exceptions.SSLError: HTTPSConnectionPool(host='overload.yandex.net', port=443): Max retries exceeded with url: /api/job/636995/configinitial.txt?api_token=f0abbbaf79844ac396743534e5fc5c73 (Caused by SSLError(SSLError("bad handshake: Error([('SSL routines', '', 'unexpected eof while reading')])")))

2023-08-27 19:30:12,990	Network error, will retry in 10s...
2023-08-29 14:59:15,511	Interrupting
2023-08-29 14:59:15,537	Test interrupted:
<class 'KeyboardInterrupt'>: 
  File "/usr/local/lib/python3.8/dist-packages/yandextank/core/tankworker.py", line 79, in run
    self.retcode = self.core.wait_for_finish()

  File "/usr/local/lib/python3.8/dist-packages/yandextank/core/tankcore.py", line 308, in wait_for_finish
    retcode = plugin.is_test_finished()

  File "/usr/local/lib/python3.8/dist-packages/yandextank/plugins/Console/plugin.py", line 87, in is_test_finished
    self.__console_view = self.screen.render_screen().encode('utf-8')

  File "/usr/local/lib/python3.8/dist-packages/yandextank/plugins/Console/screen.py", line 416, in render_screen
    left_lines = self.__render_left_panel()

  File "/usr/local/lib/python3.8/dist-packages/yandextank/plugins/Console/screen.py", line 369, in __render_left_panel
    left_block.render()

  File "/usr/local/lib/python3.8/dist-packages/yandextank/plugins/Console/screen.py", line 559, in render
    self.top.render(expected_width=expected_width)

  File "/usr/local/lib/python3.8/dist-packages/yandextank/plugins/Console/screen.py", line 560, in render
    self.bottom.render(expected_width=expected_width)

  File "/usr/local/lib/python3.8/dist-packages/yandextank/plugins/Console/screen.py", line 526, in render
    self.left.render(expected_width=expected_width)

  File "/usr/local/lib/python3.8/dist-packages/yandextank/plugins/Console/screen.py", line 695, in render
    data = self.__calc_percentiles()

  File "/usr/local/lib/python3.8/dist-packages/yandextank/plugins/Console/screen.py", line 675, in __calc_percentiles
    last_1m = last_1m.add(data, fill_value=0)

  File "/usr/local/lib/python3.8/dist-packages/pandas/core/ops/__init__.py", line 165, in flex_wrapper
    return self._binop(other, op, level=level, fill_value=fill_value)

  File "/usr/local/lib/python3.8/dist-packages/pandas/core/series.py", line 2723, in _binop
    this, other = self.align(other, level=level, join="outer", copy=False)

  File "/usr/local/lib/python3.8/dist-packages/pandas/core/series.py", line 4220, in align
    return super().align(

  File "/usr/local/lib/python3.8/dist-packages/pandas/core/generic.py", line 8825, in align
    return self._align_series(

  File "/usr/local/lib/python3.8/dist-packages/pandas/core/generic.py", line 8938, in _align_series
    left = self._reindex_indexer(join_index, lidx, copy)

  File "/usr/local/lib/python3.8/dist-packages/pandas/core/series.py", line 4193, in _reindex_indexer
    return self._constructor(new_values, index=new_index)

  File "/usr/local/lib/python3.8/dist-packages/pandas/core/series.py", line 366, in __init__
    data = SingleBlockManager.from_array(data, index)

  File "/usr/local/lib/python3.8/dist-packages/pandas/core/internals/managers.py", line 1582, in from_array
    block = make_block(array, placement=slice(0, len(index)), ndim=1)

  File "/usr/local/lib/python3.8/dist-packages/pandas/core/internals/blocks.py", line 2744, in make_block
    klass = get_block_type(values, dtype)

  File "/usr/local/lib/python3.8/dist-packages/pandas/core/internals/blocks.py", line 2709, in get_block_type
    elif is_interval_dtype(dtype) or is_period_dtype(dtype):

  File "/usr/local/lib/python3.8/dist-packages/pandas/core/dtypes/common.py", line 496, in is_period_dtype
    return PeriodDtype.is_dtype(arr_or_dtype)

  File "/usr/local/lib/python3.8/dist-packages/pandas/core/dtypes/dtypes.py", line 942, in is_dtype
    return super().is_dtype(dtype)

  File "/usr/local/lib/python3.8/dist-packages/pandas/core/dtypes/base.py", line 280, in is_dtype
    if isinstance(dtype, (ABCSeries, ABCIndexClass, ABCDataFrame, np.dtype)):

  File "/usr/local/lib/python3.8/dist-packages/pandas/core/dtypes/generic.py", line 32, in _check
    return getattr(inst, attr, "_typ") in comp

